/var/lib/slurm-llnl/slurmd/job5193806/slurm_script: line 24: /dss/dsshome1/0B/di38wip/RAG_Style/scripts/async/start_vllm.sh: No such file or directory
Traceback (most recent call last):
  File "/dss/dsshome1/0B/di38wip/miniconda3/lib/python3.12/site-packages/httpx/_transports/default.py", line 72, in map_httpcore_exceptions
    yield
  File "/dss/dsshome1/0B/di38wip/miniconda3/lib/python3.12/site-packages/httpx/_transports/default.py", line 377, in handle_async_request
    resp = await self._pool.handle_async_request(req)
           ^^^^^^^^^^^^^^^^^^^^^^^^^^^^^^^^^^^^^^^^^^
  File "/dss/dsshome1/0B/di38wip/miniconda3/lib/python3.12/site-packages/httpcore/_async/connection_pool.py", line 256, in handle_async_request
    raise exc from None
  File "/dss/dsshome1/0B/di38wip/miniconda3/lib/python3.12/site-packages/httpcore/_async/connection_pool.py", line 236, in handle_async_request
    response = await connection.handle_async_request(
               ^^^^^^^^^^^^^^^^^^^^^^^^^^^^^^^^^^^^^^
  File "/dss/dsshome1/0B/di38wip/miniconda3/lib/python3.12/site-packages/httpcore/_async/connection.py", line 101, in handle_async_request
    raise exc
  File "/dss/dsshome1/0B/di38wip/miniconda3/lib/python3.12/site-packages/httpcore/_async/connection.py", line 78, in handle_async_request
    stream = await self._connect(request)
             ^^^^^^^^^^^^^^^^^^^^^^^^^^^^
  File "/dss/dsshome1/0B/di38wip/miniconda3/lib/python3.12/site-packages/httpcore/_async/connection.py", line 124, in _connect
    stream = await self._network_backend.connect_tcp(**kwargs)
             ^^^^^^^^^^^^^^^^^^^^^^^^^^^^^^^^^^^^^^^^^^^^^^^^^
  File "/dss/dsshome1/0B/di38wip/miniconda3/lib/python3.12/site-packages/httpcore/_backends/auto.py", line 31, in connect_tcp
    return await self._backend.connect_tcp(
           ^^^^^^^^^^^^^^^^^^^^^^^^^^^^^^^^
  File "/dss/dsshome1/0B/di38wip/miniconda3/lib/python3.12/site-packages/httpcore/_backends/anyio.py", line 113, in connect_tcp
    with map_exceptions(exc_map):
         ^^^^^^^^^^^^^^^^^^^^^^^
  File "/dss/dsshome1/0B/di38wip/miniconda3/lib/python3.12/contextlib.py", line 158, in __exit__
    self.gen.throw(value)
  File "/dss/dsshome1/0B/di38wip/miniconda3/lib/python3.12/site-packages/httpcore/_exceptions.py", line 14, in map_exceptions
    raise to_exc(exc) from exc
httpcore.ConnectError: All connection attempts failed

The above exception was the direct cause of the following exception:

Traceback (most recent call last):
  File "/dss/dsshome1/0B/di38wip/miniconda3/lib/python3.12/site-packages/openai/_base_client.py", line 1576, in _request
    response = await self._client.send(
               ^^^^^^^^^^^^^^^^^^^^^^^^
  File "/dss/dsshome1/0B/di38wip/miniconda3/lib/python3.12/site-packages/httpx/_client.py", line 1674, in send
    response = await self._send_handling_auth(
               ^^^^^^^^^^^^^^^^^^^^^^^^^^^^^^^
  File "/dss/dsshome1/0B/di38wip/miniconda3/lib/python3.12/site-packages/httpx/_client.py", line 1702, in _send_handling_auth
    response = await self._send_handling_redirects(
               ^^^^^^^^^^^^^^^^^^^^^^^^^^^^^^^^^^^^
  File "/dss/dsshome1/0B/di38wip/miniconda3/lib/python3.12/site-packages/httpx/_client.py", line 1739, in _send_handling_redirects
    response = await self._send_single_request(request)
               ^^^^^^^^^^^^^^^^^^^^^^^^^^^^^^^^^^^^^^^^
  File "/dss/dsshome1/0B/di38wip/miniconda3/lib/python3.12/site-packages/httpx/_client.py", line 1776, in _send_single_request
    response = await transport.handle_async_request(request)
               ^^^^^^^^^^^^^^^^^^^^^^^^^^^^^^^^^^^^^^^^^^^^^
  File "/dss/dsshome1/0B/di38wip/miniconda3/lib/python3.12/site-packages/httpx/_transports/default.py", line 376, in handle_async_request
    with map_httpcore_exceptions():
         ^^^^^^^^^^^^^^^^^^^^^^^^^
  File "/dss/dsshome1/0B/di38wip/miniconda3/lib/python3.12/contextlib.py", line 158, in __exit__
    self.gen.throw(value)
  File "/dss/dsshome1/0B/di38wip/miniconda3/lib/python3.12/site-packages/httpx/_transports/default.py", line 89, in map_httpcore_exceptions
    raise mapped_exc(message) from exc
httpx.ConnectError: All connection attempts failed

The above exception was the direct cause of the following exception:

Traceback (most recent call last):
  File "/dss/dsshome1/0B/di38wip/ImpliRet/RAG_Style/scripts/async/async_run_tests.py", line 94, in <module>
    main()
  File "/dss/dsshome1/0B/di38wip/ImpliRet/RAG_Style/scripts/async/async_run_tests.py", line 89, in main
    tester.evaluate()
  File "/dss/dsshome1/0B/di38wip/ImpliRet/RAG_Style/scripts/async/async_evaluate.py", line 448, in evaluate
    results = loop.run_until_complete(asyncio.gather(*tasks))
              ^^^^^^^^^^^^^^^^^^^^^^^^^^^^^^^^^^^^^^^^^^^^^^^
  File "/dss/dsshome1/0B/di38wip/miniconda3/lib/python3.12/asyncio/base_events.py", line 685, in run_until_complete
    return future.result()
           ^^^^^^^^^^^^^^^
  File "/dss/dsshome1/0B/di38wip/ImpliRet/RAG_Style/scripts/async/async_evaluate.py", line 402, in _run_one
    resp = await self.api.generate_response(
           ^^^^^^^^^^^^^^^^^^^^^^^^^^^^^^^^^
  File "/dss/dsshome1/0B/di38wip/ImpliRet/RAG_Style/scripts/async/async_api_connector.py", line 188, in generate_response
    completion = await _call_openai()
                 ^^^^^^^^^^^^^^^^^^^^
  File "/dss/dsshome1/0B/di38wip/miniconda3/lib/python3.12/site-packages/tenacity/asyncio/__init__.py", line 189, in async_wrapped
    return await copy(fn, *args, **kwargs)
           ^^^^^^^^^^^^^^^^^^^^^^^^^^^^^^^
  File "/dss/dsshome1/0B/di38wip/miniconda3/lib/python3.12/site-packages/tenacity/asyncio/__init__.py", line 111, in __call__
    do = await self.iter(retry_state=retry_state)
         ^^^^^^^^^^^^^^^^^^^^^^^^^^^^^^^^^^^^^^^^
  File "/dss/dsshome1/0B/di38wip/miniconda3/lib/python3.12/site-packages/tenacity/asyncio/__init__.py", line 153, in iter
    result = await action(retry_state)
             ^^^^^^^^^^^^^^^^^^^^^^^^^
  File "/dss/dsshome1/0B/di38wip/miniconda3/lib/python3.12/site-packages/tenacity/_utils.py", line 99, in inner
    return call(*args, **kwargs)
           ^^^^^^^^^^^^^^^^^^^^^
  File "/dss/dsshome1/0B/di38wip/miniconda3/lib/python3.12/site-packages/tenacity/__init__.py", line 398, in <lambda>
    self._add_action_func(lambda rs: rs.outcome.result())
                                     ^^^^^^^^^^^^^^^^^^^
  File "/dss/dsshome1/0B/di38wip/miniconda3/lib/python3.12/concurrent/futures/_base.py", line 449, in result
    return self.__get_result()
           ^^^^^^^^^^^^^^^^^^^
  File "/dss/dsshome1/0B/di38wip/miniconda3/lib/python3.12/concurrent/futures/_base.py", line 401, in __get_result
    raise self._exception
  File "/dss/dsshome1/0B/di38wip/miniconda3/lib/python3.12/site-packages/tenacity/asyncio/__init__.py", line 114, in __call__
    result = await fn(*args, **kwargs)
             ^^^^^^^^^^^^^^^^^^^^^^^^^
  File "/dss/dsshome1/0B/di38wip/ImpliRet/RAG_Style/scripts/async/async_api_connector.py", line 175, in _call_openai
    return await self.api.chat.completions.create(
           ^^^^^^^^^^^^^^^^^^^^^^^^^^^^^^^^^^^^^^^
  File "/dss/dsshome1/0B/di38wip/miniconda3/lib/python3.12/site-packages/openai/resources/chat/completions.py", line 1720, in create
    return await self._post(
           ^^^^^^^^^^^^^^^^^
  File "/dss/dsshome1/0B/di38wip/miniconda3/lib/python3.12/site-packages/openai/_base_client.py", line 1843, in post
    return await self.request(cast_to, opts, stream=stream, stream_cls=stream_cls)
           ^^^^^^^^^^^^^^^^^^^^^^^^^^^^^^^^^^^^^^^^^^^^^^^^^^^^^^^^^^^^^^^^^^^^^^^
  File "/dss/dsshome1/0B/di38wip/miniconda3/lib/python3.12/site-packages/openai/_base_client.py", line 1537, in request
    return await self._request(
           ^^^^^^^^^^^^^^^^^^^^
  File "/dss/dsshome1/0B/di38wip/miniconda3/lib/python3.12/site-packages/openai/_base_client.py", line 1600, in _request
    return await self._retry_request(
           ^^^^^^^^^^^^^^^^^^^^^^^^^^
  File "/dss/dsshome1/0B/di38wip/miniconda3/lib/python3.12/site-packages/openai/_base_client.py", line 1670, in _retry_request
    return await self._request(
           ^^^^^^^^^^^^^^^^^^^^
  File "/dss/dsshome1/0B/di38wip/miniconda3/lib/python3.12/site-packages/openai/_base_client.py", line 1600, in _request
    return await self._retry_request(
           ^^^^^^^^^^^^^^^^^^^^^^^^^^
  File "/dss/dsshome1/0B/di38wip/miniconda3/lib/python3.12/site-packages/openai/_base_client.py", line 1670, in _retry_request
    return await self._request(
           ^^^^^^^^^^^^^^^^^^^^
  File "/dss/dsshome1/0B/di38wip/miniconda3/lib/python3.12/site-packages/openai/_base_client.py", line 1600, in _request
    return await self._retry_request(
           ^^^^^^^^^^^^^^^^^^^^^^^^^^
  File "/dss/dsshome1/0B/di38wip/miniconda3/lib/python3.12/site-packages/openai/_base_client.py", line 1670, in _retry_request
    return await self._request(
           ^^^^^^^^^^^^^^^^^^^^
  File "/dss/dsshome1/0B/di38wip/miniconda3/lib/python3.12/site-packages/openai/_base_client.py", line 1610, in _request
    raise APIConnectionError(request=request) from err
openai.APIConnectionError: Connection error.
kill: usage: kill [-s sigspec | -n signum | -sigspec] pid | jobspec ... or kill -l [sigspec]
Traceback (most recent call last):
  File "/dss/dsshome1/0B/di38wip/miniconda3/lib/python3.12/site-packages/httpx/_transports/default.py", line 72, in map_httpcore_exceptions
    yield
  File "/dss/dsshome1/0B/di38wip/miniconda3/lib/python3.12/site-packages/httpx/_transports/default.py", line 377, in handle_async_request
    resp = await self._pool.handle_async_request(req)
           ^^^^^^^^^^^^^^^^^^^^^^^^^^^^^^^^^^^^^^^^^^
  File "/dss/dsshome1/0B/di38wip/miniconda3/lib/python3.12/site-packages/httpcore/_async/connection_pool.py", line 256, in handle_async_request
    raise exc from None
  File "/dss/dsshome1/0B/di38wip/miniconda3/lib/python3.12/site-packages/httpcore/_async/connection_pool.py", line 236, in handle_async_request
    response = await connection.handle_async_request(
               ^^^^^^^^^^^^^^^^^^^^^^^^^^^^^^^^^^^^^^
  File "/dss/dsshome1/0B/di38wip/miniconda3/lib/python3.12/site-packages/httpcore/_async/connection.py", line 101, in handle_async_request
    raise exc
  File "/dss/dsshome1/0B/di38wip/miniconda3/lib/python3.12/site-packages/httpcore/_async/connection.py", line 78, in handle_async_request
    stream = await self._connect(request)
             ^^^^^^^^^^^^^^^^^^^^^^^^^^^^
  File "/dss/dsshome1/0B/di38wip/miniconda3/lib/python3.12/site-packages/httpcore/_async/connection.py", line 124, in _connect
    stream = await self._network_backend.connect_tcp(**kwargs)
             ^^^^^^^^^^^^^^^^^^^^^^^^^^^^^^^^^^^^^^^^^^^^^^^^^
  File "/dss/dsshome1/0B/di38wip/miniconda3/lib/python3.12/site-packages/httpcore/_backends/auto.py", line 31, in connect_tcp
    return await self._backend.connect_tcp(
           ^^^^^^^^^^^^^^^^^^^^^^^^^^^^^^^^
  File "/dss/dsshome1/0B/di38wip/miniconda3/lib/python3.12/site-packages/httpcore/_backends/anyio.py", line 113, in connect_tcp
    with map_exceptions(exc_map):
         ^^^^^^^^^^^^^^^^^^^^^^^
  File "/dss/dsshome1/0B/di38wip/miniconda3/lib/python3.12/contextlib.py", line 158, in __exit__
    self.gen.throw(value)
  File "/dss/dsshome1/0B/di38wip/miniconda3/lib/python3.12/site-packages/httpcore/_exceptions.py", line 14, in map_exceptions
    raise to_exc(exc) from exc
httpcore.ConnectError: All connection attempts failed

The above exception was the direct cause of the following exception:

Traceback (most recent call last):
  File "/dss/dsshome1/0B/di38wip/miniconda3/lib/python3.12/site-packages/openai/_base_client.py", line 1576, in _request
    response = await self._client.send(
               ^^^^^^^^^^^^^^^^^^^^^^^^
  File "/dss/dsshome1/0B/di38wip/miniconda3/lib/python3.12/site-packages/httpx/_client.py", line 1674, in send
    response = await self._send_handling_auth(
               ^^^^^^^^^^^^^^^^^^^^^^^^^^^^^^^
  File "/dss/dsshome1/0B/di38wip/miniconda3/lib/python3.12/site-packages/httpx/_client.py", line 1702, in _send_handling_auth
    response = await self._send_handling_redirects(
               ^^^^^^^^^^^^^^^^^^^^^^^^^^^^^^^^^^^^
  File "/dss/dsshome1/0B/di38wip/miniconda3/lib/python3.12/site-packages/httpx/_client.py", line 1739, in _send_handling_redirects
    response = await self._send_single_request(request)
               ^^^^^^^^^^^^^^^^^^^^^^^^^^^^^^^^^^^^^^^^
  File "/dss/dsshome1/0B/di38wip/miniconda3/lib/python3.12/site-packages/httpx/_client.py", line 1776, in _send_single_request
    response = await transport.handle_async_request(request)
               ^^^^^^^^^^^^^^^^^^^^^^^^^^^^^^^^^^^^^^^^^^^^^
  File "/dss/dsshome1/0B/di38wip/miniconda3/lib/python3.12/site-packages/httpx/_transports/default.py", line 376, in handle_async_request
    with map_httpcore_exceptions():
         ^^^^^^^^^^^^^^^^^^^^^^^^^
  File "/dss/dsshome1/0B/di38wip/miniconda3/lib/python3.12/contextlib.py", line 158, in __exit__
    self.gen.throw(value)
  File "/dss/dsshome1/0B/di38wip/miniconda3/lib/python3.12/site-packages/httpx/_transports/default.py", line 89, in map_httpcore_exceptions
    raise mapped_exc(message) from exc
httpx.ConnectError: All connection attempts failed

The above exception was the direct cause of the following exception:

Traceback (most recent call last):
  File "/dss/dsshome1/0B/di38wip/ImpliRet/./RAG_Style/scripts/async/async_run_tests.py", line 94, in <module>
    main()
  File "/dss/dsshome1/0B/di38wip/ImpliRet/./RAG_Style/scripts/async/async_run_tests.py", line 89, in main
    tester.evaluate()
  File "/dss/dsshome1/0B/di38wip/ImpliRet/RAG_Style/scripts/async/async_evaluate.py", line 448, in evaluate
    results = loop.run_until_complete(asyncio.gather(*tasks))
              ^^^^^^^^^^^^^^^^^^^^^^^^^^^^^^^^^^^^^^^^^^^^^^^
  File "/dss/dsshome1/0B/di38wip/miniconda3/lib/python3.12/asyncio/base_events.py", line 685, in run_until_complete
    return future.result()
           ^^^^^^^^^^^^^^^
  File "/dss/dsshome1/0B/di38wip/ImpliRet/RAG_Style/scripts/async/async_evaluate.py", line 402, in _run_one
    resp = await self.api.generate_response(
           ^^^^^^^^^^^^^^^^^^^^^^^^^^^^^^^^^
  File "/dss/dsshome1/0B/di38wip/ImpliRet/RAG_Style/scripts/async/async_api_connector.py", line 188, in generate_response
    completion = await _call_openai()
                 ^^^^^^^^^^^^^^^^^^^^
  File "/dss/dsshome1/0B/di38wip/miniconda3/lib/python3.12/site-packages/tenacity/asyncio/__init__.py", line 189, in async_wrapped
    return await copy(fn, *args, **kwargs)
           ^^^^^^^^^^^^^^^^^^^^^^^^^^^^^^^
  File "/dss/dsshome1/0B/di38wip/miniconda3/lib/python3.12/site-packages/tenacity/asyncio/__init__.py", line 111, in __call__
    do = await self.iter(retry_state=retry_state)
         ^^^^^^^^^^^^^^^^^^^^^^^^^^^^^^^^^^^^^^^^
  File "/dss/dsshome1/0B/di38wip/miniconda3/lib/python3.12/site-packages/tenacity/asyncio/__init__.py", line 153, in iter
    result = await action(retry_state)
             ^^^^^^^^^^^^^^^^^^^^^^^^^
  File "/dss/dsshome1/0B/di38wip/miniconda3/lib/python3.12/site-packages/tenacity/_utils.py", line 99, in inner
    return call(*args, **kwargs)
           ^^^^^^^^^^^^^^^^^^^^^
  File "/dss/dsshome1/0B/di38wip/miniconda3/lib/python3.12/site-packages/tenacity/__init__.py", line 398, in <lambda>
    self._add_action_func(lambda rs: rs.outcome.result())
                                     ^^^^^^^^^^^^^^^^^^^
  File "/dss/dsshome1/0B/di38wip/miniconda3/lib/python3.12/concurrent/futures/_base.py", line 449, in result
    return self.__get_result()
           ^^^^^^^^^^^^^^^^^^^
  File "/dss/dsshome1/0B/di38wip/miniconda3/lib/python3.12/concurrent/futures/_base.py", line 401, in __get_result
    raise self._exception
  File "/dss/dsshome1/0B/di38wip/miniconda3/lib/python3.12/site-packages/tenacity/asyncio/__init__.py", line 114, in __call__
    result = await fn(*args, **kwargs)
             ^^^^^^^^^^^^^^^^^^^^^^^^^
  File "/dss/dsshome1/0B/di38wip/ImpliRet/RAG_Style/scripts/async/async_api_connector.py", line 175, in _call_openai
    return await self.api.chat.completions.create(
           ^^^^^^^^^^^^^^^^^^^^^^^^^^^^^^^^^^^^^^^
  File "/dss/dsshome1/0B/di38wip/miniconda3/lib/python3.12/site-packages/openai/resources/chat/completions.py", line 1720, in create
    return await self._post(
           ^^^^^^^^^^^^^^^^^
  File "/dss/dsshome1/0B/di38wip/miniconda3/lib/python3.12/site-packages/openai/_base_client.py", line 1843, in post
    return await self.request(cast_to, opts, stream=stream, stream_cls=stream_cls)
           ^^^^^^^^^^^^^^^^^^^^^^^^^^^^^^^^^^^^^^^^^^^^^^^^^^^^^^^^^^^^^^^^^^^^^^^
  File "/dss/dsshome1/0B/di38wip/miniconda3/lib/python3.12/site-packages/openai/_base_client.py", line 1537, in request
    return await self._request(
           ^^^^^^^^^^^^^^^^^^^^
  File "/dss/dsshome1/0B/di38wip/miniconda3/lib/python3.12/site-packages/openai/_base_client.py", line 1600, in _request
    return await self._retry_request(
           ^^^^^^^^^^^^^^^^^^^^^^^^^^
  File "/dss/dsshome1/0B/di38wip/miniconda3/lib/python3.12/site-packages/openai/_base_client.py", line 1670, in _retry_request
    return await self._request(
           ^^^^^^^^^^^^^^^^^^^^
  File "/dss/dsshome1/0B/di38wip/miniconda3/lib/python3.12/site-packages/openai/_base_client.py", line 1600, in _request
    return await self._retry_request(
           ^^^^^^^^^^^^^^^^^^^^^^^^^^
  File "/dss/dsshome1/0B/di38wip/miniconda3/lib/python3.12/site-packages/openai/_base_client.py", line 1670, in _retry_request
    return await self._request(
           ^^^^^^^^^^^^^^^^^^^^
  File "/dss/dsshome1/0B/di38wip/miniconda3/lib/python3.12/site-packages/openai/_base_client.py", line 1600, in _request
    return await self._retry_request(
           ^^^^^^^^^^^^^^^^^^^^^^^^^^
  File "/dss/dsshome1/0B/di38wip/miniconda3/lib/python3.12/site-packages/openai/_base_client.py", line 1670, in _retry_request
    return await self._request(
           ^^^^^^^^^^^^^^^^^^^^
  File "/dss/dsshome1/0B/di38wip/miniconda3/lib/python3.12/site-packages/openai/_base_client.py", line 1610, in _request
    raise APIConnectionError(request=request) from err
openai.APIConnectionError: Connection error.
kill: usage: kill [-s sigspec | -n signum | -sigspec] pid | jobspec ... or kill -l [sigspec]
