Traceback (most recent call last):
  File "/dss/dsshome1/0B/di38wip/ImpliRet/./RAG_Style/scripts/sync/sync_run_tests.py", line 93, in <module>
    main()
  File "/dss/dsshome1/0B/di38wip/ImpliRet/./RAG_Style/scripts/sync/sync_run_tests.py", line 88, in main
    tester.evaluate()
  File "/dss/dsshome1/0B/di38wip/ImpliRet/RAG_Style/scripts/sync/sync_evaluation.py", line 342, in evaluate
    prompts = [self._get_prompt(idx, ex) for idx, ex in enumerate(self.examples)]
               ^^^^^^^^^^^^^^^^^^^^^^^^^
  File "/dss/dsshome1/0B/di38wip/ImpliRet/RAG_Style/scripts/sync/sync_evaluation.py", line 328, in _get_prompt
    context_block = self._select_context(idx)
                    ^^^^^^^^^^^^^^^^^^^^^^^^^
  File "/dss/dsshome1/0B/di38wip/ImpliRet/RAG_Style/scripts/sync/sync_evaluation.py", line 314, in _select_context
    context_convs = self._get_context_convs(self.conversations_list, golden_index, self.k, retrieved_indices)
                    ^^^^^^^^^^^^^^^^^^^^^^^^^^^^^^^^^^^^^^^^^^^^^^^^^^^^^^^^^^^^^^^^^^^^^^^^^^^^^^^^^^^^^^^^^
  File "/dss/dsshome1/0B/di38wip/ImpliRet/RAG_Style/scripts/sync/sync_evaluation.py", line 275, in _get_context_convs
    context_convs = [conversations[idx] for idx in top_k_indices]
                     ~~~~~~~~~~~~~^^^^^
IndexError: list index out of range
